Workbook
Name ASCASCASCASDCD: #REF!
Name ASCASCASCASDCD: #REF!
Name AWSEDRFTGYHU: #REF!
Name AWSEDRFTGYHU: #REF!
Name AYUDANTE: #REF!
Name AYUDANTE: #REF!
Name AYUDANTE: #REF!
Name AYUDANTE: #REF!
Name AYUDANTE: #REF!
Name AYUDANTES: #REF!
Name AYUDANTES: #REF!
Name AYUDANTES: #REF!
Name AYUDANTES: #REF!
Name AYUDANTES: #REF!
Name AYUDANTESCA: #REF!
Name AYUDANTESCA: #REF!
Name CARGOS: #REF!
Name CARGOS: #REF!
Name CARGOS: #REF!
Name CARGOS: #REF!
Name CARGOS: #REF!
Name CE15W40: #REF!
Name CE15W40: #REF!
Name CE15W40: #REF!
Name CEDULAS: #REF!
Name CEDULAS: #REF!
Name CEDULAS: #REF!
Name CEDULAS: #REF!
Name CEDULAS: #REF!
Name CHODER: #REF!
Name CHODER: #REF!
Name CHODER: #REF!
Name CHODER: #REF!
Name CHODER: #REF!
Name CHOFER: #REF!
Name CHOFER: #REF!
Name CHOFER: #REF!
Name CHOFER: #REF!
Name CHOFER: #REF!
Name CHOFER2: #REF!
Name CHOFER2: #REF!
Name DBFBDGHKILYHJDGARE: #REF!
Name DBFBDGHKILYHJDGARE: #REF!
Name FDSA: #REF!
Name FDSA: #REF!
Name GASOLINA: #REF!
Name GASOLINA: #REF!
Name GASOLINA: #REF!
Name GASOLINA: #REF!
Name GASOLINA: #REF!
Name henry: #REF!
Name henry: #REF!
Name ijijim: #REF!
Name ijijim: #REF!
Name IOKIJUHYGTFRD: #REF!
Name IOKIJUHYGTFRD: #REF!
Name IOKIJUHYGTFRD: #REF!
Name IstUnidades: #REF!
Name IstUnidades: #REF!
Name IstUnidades: #REF!

Sheet 15W-40
C1: RELACIÓN DE CONSUMO DE LUBRICANTE | H1: CAM-FR-AD-010
H2: Fecha: 07/2026
H3: Revisión: 0
H4: Pagina: 1 de 1
K7: =5*19 -> 95
B8: ENTRADA | D8: SALIDA
A9: FECHA | B9: PROVEEDOR | C9: CANTIDAD | D9: SOLICITANTE | E9: EQUIPO | F9: CANTIDAD2 | G9: N° NOTA DE ENTREGA | H9: EXISTENCIA
A10: 46231 | B10: ENVISERCA | C10: 228 | D10: OBRA | E10: MAQUINARIAS | F10: 36 | G10: N-IRT-005 | H10: =Table_2[[#This Row],[CANTIDAD]]-Table_2[[#This Row],[CANTIDAD2]] -> 192
A11: 46232 | D11: VP | E11: MAQUINARIAS | F11: 54 | G11: N-IRT-007 | H11: =H10-Table_2[[#This Row],[CANTIDAD2]] -> 138
A12: 46234 | D12: TALLER | E12: TAMPO PS-150C | F12: 4 | H12: =H11-Table_2[[#This Row],[CANTIDAD2]] -> 134
A13: 46234 | D13: TALLER | E13: FINNISH PF-172 | F13: 1.5 | H13: =H12-Table_2[[#This Row],[CANTIDAD2]] -> 132.5
A14: 46237 | D14: OBRA | E14: MAQUINARIAS | F14: 19 | H14: =H13-Table_2[[#This Row],[CANTIDAD2]] -> 113.5
A15: 46237 | D15: TALLER | E15: VP-1-001 | F15: 2 | H15: =H14-Table_2[[#This Row],[CANTIDAD2]] -> 111.5
A16: 46237 | D16: TALLER | E16: TP 11-002 | F16: 1.5 | H16: =H15-Table_2[[#This Row],[CANTIDAD2]] -> 110
A17: 46251 | D17: VP | E17: MAQUINARIAS | F17: 57 | H17: =H16-Table_2[[#This Row],[CANTIDAD2]] -> 53
A18: 46254 | B18: ENVISERCA | C18: 95 | H18: =H17+Table_2[[#This Row],[CANTIDAD]] -> 148
A19: 46254 | D19: TALLER | E19: VC 8-001 | F19: 7 | H19: =H18-Table_2[[#This Row],[CANTIDAD2]] -> 141
A20: 46258 | D20: OBRA | E20: ENTREGADOS ALBERTO OBRA | F20: 19 | H20: =H19-Table_2[[#This Row],[CANTIDAD2]] -> 122
A21: 46263 | D21: VP | E21: ENTREGADOS ALBERTO | F21: 19 | H21: =H20-Table_2[[#This Row],[CANTIDAD2]] -> 103
A22: 46263 | D22: TALLER | E22: CARGADOR 928G | F22: 20 | H22: =H21-Table_2[[#This Row],[CANTIDAD2]] -> 83
A23: 46263 | D23: TALLER | E23: TP 11-002 | F23: 3 | H23: =H22-Table_2[[#This Row],[CANTIDAD2]] -> 80
A24: 46268 | D24: TALLER | E24: VL 2-001 | F24: 19 | H24: =H23-Table_2[[#This Row],[CANTIDAD2]] -> 61
A25: 46269 | D25: TALLER | E25: RETRO 420D | F25: 2 | H25: =H24-Table_2[[#This Row],[CANTIDAD2]] -> 59
A26: 46273 | D26: TALLER | E26: 21 | F26: 1 | H26: =H25-Table_2[[#This Row],[CANTIDAD2]] -> 58
A27: 46279 | D27: TALLER | E27: CARGO 815 PLATAFORMA | F27: 3 | H27: =H26-Table_2[[#This Row],[CANTIDAD2]] -> 55
A28: 46280 | D28: VP | E28: JUMBO | F28: 19 | H28: =H27-Table_2[[#This Row],[CANTIDAD2]] -> 36
A29: 46281 | D29: TALLER | E29: CARGO 815 BACHEO | F29: 19 | H29: =H28-Table_2[[#This Row],[CANTIDAD2]] -> 17
A30: 46283 | B30: ENVISERCA | C30: 114 | H30: =H29+Table_2[[#This Row],[CANTIDAD]] -> 131
A31: 46284 | D31: TALLER | E31: 31 | F31: 2 | H31: =H30-Table_2[[#This Row],[CANTIDAD2]] -> 129
A32: 46286 | D32: OBRA | E32: MAQUINARIAS | F32: 38 | H32: =H31-Table_2[[#This Row],[CANTIDAD2]] -> 91
A33: 46286 | D33: VP | E33: MAQUINARIAS | F33: 19 | H33: =H32-Table_2[[#This Row],[CANTIDAD2]] -> 72
A34: 46291 | D34: TALLER | E34: CARGO 1721 | F34: 10 | H34: =H33-Table_2[[#This Row],[CANTIDAD2]] -> 62
A35: 46294 | D35: OBRA | E35: RETRO 420D | F35: 2 | H35: =H34-Table_2[[#This Row],[CANTIDAD2]] -> 60
A36: 46295 | D36: TALLER | E36: CARGADOR 928G | F36: 5 | H36: =H35-Table_2[[#This Row],[CANTIDAD2]] -> 55
A37: 46296 | D37: OBRA | E37: CARGO 815 TRANSPORTE | F37: 2 | H37: =H36-Table_2[[#This Row],[CANTIDAD2]] -> 53
H38: =H37-Table_2[[#This Row],[CANTIDAD2]] -> 53
H39: =H38-Table_2[[#This Row],[CANTIDAD2]] -> 53
H40: =H39-Table_2[[#This Row],[CANTIDAD2]] -> 53
H41: =H40-Table_2[[#This Row],[CANTIDAD2]] -> 53
H42: =H41-Table_2[[#This Row],[CANTIDAD2]] -> 53
...

Sheet SAE 50
C1: RELACIÓN DE CONSUMO DE LUBRICANTE | H1: CAM-FR-AD-010
H2: Fecha: 07/2026
H3: Revisión: 0
H4: Pagina: 1 de 1
M6: =6*19 -> 114
L7: =19*2+3 -> 41
B8: ENTRADA | D8: SALIDA
A9: FECHA | B9: PROVEEDOR | C9: CANTIDAD | D9: SOLICITANTE | E9: EQUIPO | F9: CANTIDAD2 | G9: N° NOTA DE ENTREGA | H9: EXISTENCIA
B10: EXISTENCIA | C10: 10 | H10: =Table_22[[#This Row],[CANTIDAD]]-Table_22[[#This Row],[CANTIDAD2]] -> 10
A11: 46231 | B11: ENVISERCA | C11: 114 | H11: =H10+Table_22[[#This Row],[CANTIDAD]] -> 124
A12: 46231 | B12: ENVISERCA | C12: 114 | D12: OBRA | E12: MAQUINARIAS | F12: 36 | G12: N-IRT-005 | H12: =H11-Table_22[[#This Row],[CANTIDAD2]] -> 88 | L12: =41-28.5 -> 12.5
A13: 46232 | D13: VP | E13: MAQUINARIAS | F13: 18 | G13: N-IRT-007 | H13: =H12-Table_22[[#This Row],[CANTIDAD2]] -> 70
A14: 46234 | D14: TALLER | E14: TAMPO PS-150C | F14: 2 | H14: =H13-Table_22[[#This Row],[CANTIDAD2]] -> 68
A15: 46234 | D15: TALLER | E15: FINNISH PF-172 | F15: 1.5 | H15: =H14-Table_22[[#This Row],[CANTIDAD2]] -> 66.5
A16: 46235 | D16: TALLER | E16: CARAGADOR 928G | F16: 6 | H16: =H15-Table_22[[#This Row],[CANTIDAD2]] -> 60.5
A17: 46237 | D17: OBRA | E17: MAQUINARIAS | F17: 19 | H17: =H16-Table_22[[#This Row],[CANTIDAD2]] -> 41.5
A18: 46237 | D18: OBRA | E18: RETRO 416 | F18: 5 | H18: =H17-Table_22[[#This Row],[CANTIDAD2]] -> 36.5
A19: 46238 | D19: OBRA | E19: RETRO 420 | F19: 3 | H19: =H18-Table_22[[#This Row],[CANTIDAD2]] -> 33.5
A20: 46239 | D20: OBRA | E20: RETRO 420 | F20: 3 | H20: =H19-Table_22[[#This Row],[CANTIDAD2]] -> 30.5
A21: 46240 | D21: OBRA | E21: RETRO 420 | F21: 1 | H21: =H20-Table_22[[#This Row],[CANTIDAD2]] -> 29.5
A22: 46247 | D22: OBRA | E22: SC 13-001 | F22: 2 | H22: =H21-Table_22[[#This Row],[CANTIDAD2]] -> 27.5
A23: 46251 | D23: OBRA | E23: VP 4-001 | F23: 1.5 | H23: =H22-Table_22[[#This Row],[CANTIDAD2]] -> 26
A24: 46251 | D24: OBRA | E24: TP 11-002 | F24: 2 | H24: =H23-Table_22[[#This Row],[CANTIDAD2]] -> 24
A25: 46252 | D25: OBRA | E25: RETRO 420 | F25: 2 | H25: =H24-Table_22[[#This Row],[CANTIDAD2]] -> 22
... A27: 46252 | D27: TALLER | E27: CARAGADOR 966 | F27: 19 | H27: =H26-Table_22[[#This Row],[CANTIDAD2]] -> 1.5
A28: 46254 | B28: ENVISERCA | C28: 95 | H28: =Table_22[[#This Row],[CANTIDAD]]+H27 -> 96.5
A29: 46254 | D29: OBRA | E29: RETRO 420D | F29: 2 | H29: =H28-Table_22[[#This Row],[CANTIDAD2]] -> 94.5
A30: 46254 | D30: TALLER | E30: VL 2-002 | F30: 1.5 | H30: =H29-Table_22[[#This Row],[CANTIDAD2]] -> 93
A31: 46254 | D31: TALLER | E31: CARGADOR 928G | F31: 19 | H31: =H30-Table_22[[#This Row],[CANTIDAD2]] -> 74
A32: 46254 | D32: OBRA | E32: TAMPO PS-150C | F32: 3 | H32: =H31-Table_22[[#This Row],[CANTIDAD2]] -> 71
A33: 46254 | D33: TALLER | E33: CAMIONETA CHACON | F33: 1.5 | H33: =H32-Table_22[[#This Row],[CANTIDAD2]] -> 69.5
A34: 46256 | D34: TALLER | E34: VP 7-001 | F34: 19 | H34: =H33-Table_22[[#This Row],[CANTIDAD2]] -> 50.5
A35: 46258 | D35: TALLER | E35: VP 4-001 | F35: 2 | H35: =H34-Table_22[[#This Row],[CANTIDAD2]] -> 48.5
A36: 46258 | D36: OBRA | E36: RETRO 420D | F36: 1 | H36: =H35-Table_22[[#This Row],[CANTIDAD2]] -> 47.5
A37: 46258 | D37: TALLER | E37: TP 11-002 | F37: 2 | H37: =H36-Table_22[[#This Row],[CANTIDAD2]] -> 45.5
A38: 46258 | D38: OBRA | E38: ENTREGADO A ALBERTO PARA OBRA | F38: 3 | H38: =H37-Table_22[[#This Row],[CANTIDAD2]] -> 42.5
A39: 46260 | D39: OBRA | E39: RETRO 420D | F39: 1.5 | H39: =H38-Table_22[[#This Row],[CANTIDAD2]] -> 41
A40: 46260 | D40: TALLER | E40: CARGADOR 928G | F40: 19 | H40: =H39-Table_22[[#This Row],[CANTIDAD2]] -> 22
... A50: 46276 | D50: TALLER | E50: CARGO 815 PLATAFORMA | F50: 2 | H50: =H49-Table_22[[#This Row],[CANTIDAD2]] -> 3
A51: 46279 | D51: TALLER | E51: 31 | F51: 3 | H51: =H50-Table_22[[#This Row],[CANTIDAD2]] -> 0
...

Sheet GEAR 85W-140
C1: RELACIÓN DE CONSUMO DE LUBRICANTE | H1: CAM-FR-AD-010
H2: Fecha: 07/2026
H3: Revisión: 0
H4: Pagina: 1 de 1
M6: =4*19 -> 76
M7: =76+20+17 -> 113
B8: ENTRADA | D8: SALIDA
A9: FECHA | B9: PROVEEDOR | C9: CANTIDAD | D9: SOLICITANTE | E9: EQUIPO | F9: CANTIDAD2 | G9: N° NOTA DE ENTREGA | H9: EXISTENCIA
B10: EXISTENCIA | C10: 75 | H10: =Table_224[[#This Row],[CANTIDAD]]-Table_224[[#This Row],[CANTIDAD2]] -> 75
A11: 46231 | B11: ENVISERCA | C11: 38 | H11: =H10+Table_224[[#This Row],[CANTIDAD]] -> 113
A12: 46232 | D12: PLANTA | E12: REDUCTORES | F12: 2 | G12: N-IRT-006 | H12: =H11-Table_224[[#This Row],[CANTIDAD2]] -> 111
A13: 46232 | D13: PLANTA | E13: REDUCTORES | F13: 2 | H13: =H12-Table_224[[#This Row],[CANTIDAD2]] -> 109
A14: 46232 | D14: PLANTA | E14: REDUCTORES | F14: 2 | H14: =H13-Table_224[[#This Row],[CANTIDAD2]] -> 107
A15: 46265 | D15: PLANTA | E15: REDUCTORES | F15: 2 | H15: =H14-Table_224[[#This Row],[CANTIDAD2]] -> 105
A16: 46274 | D16: PLANTA | E16: REDUCTORES | F16: 2 | H16: =H15-Table_224[[#This Row],[CANTIDAD2]] -> 103
A17: 46290 | D17: TALLER | E17: VOLTEI INTERNACIONAL | F17: 38 | H17: =H16-Table_224[[#This Row],[CANTIDAD2]] -> 65
A18: 46291 | D18: TALLER | E18: CARGO 815 BACHEO ROJO | F18: 19 | H18: =H17-Table_224[[#This Row],[CANTIDAD2]] -> 46
H19: =H18-Table_224[[#This Row],[CANTIDAD2]] -> 46
H20: =H19-Table_224[[#This Row],[CANTIDAD2]] -> 46
H21: =H20-Table_224[[#This Row],[CANTIDAD2]] -> 46
H22: =H21-Table_224[[#This Row],[CANTIDAD2]] -> 46
H23: =H22-Table_224[[#This Row],[CANTIDAD2]] -> 46
H24: =H23-Table_224[[#This Row],[CANTIDAD2]] -> 46
H25: =H24-Table_224[[#This Row],[CANTIDAD2]] -> 46
H26: =H25-Table_224[[#This Row],[CANTIDAD2]] -> 46
H27: =H26-Table_224[[#This Row],[CANTIDAD2]] -> 46
H28: =H27-Table_224[[#This Row],[CANTIDAD2]] -> 46
H29: =H28-Table_224[[#This Row],[CANTIDAD2]] -> 46
H30: =H29-Table_224[[#This Row],[CANTIDAD2]] -> 46
... H42: =H41-Table_224[[#This Row],[CANTIDAD2]] -> 46
F43: =F42-'GEAR 85W-140'!$E43+'GEAR 85W-140'!$D43 -> 0 | H43: =H42-Table_224[[#This Row],[CANTIDAD2]] -> 46
H44: =H43-Table_224[[#This Row],[CANTIDAD2]] -> 46
H45: =H44-Table_224[[#This Row],[CANTIDAD2]] -> 46
H46: =H45-Table_224[[#This Row],[CANTIDAD2]] -> 46
H47: =H46-Table_224[[#This Row],[CANTIDAD2]] -> 46
H48: =H47-Table_224[[#This Row],[CANTIDAD2]] -> 46
H49: =H48-Table_224[[#This Row],[CANTIDAD2]] -> 46
H50: =H49-Table_224[[#This Row],[CANTIDAD2]] -> 46
H51: =H50-Table_224[[#This Row],[CANTIDAD2]] -> 46
H52: =H51-Table_224[[#This Row],[CANTIDAD2]] -> 46
...

Sheet GRASA LITHIUM 15 KG
C1: RELACIÓN DE CONSUMO DE LUBRICANTE | H1: CAM-FR-AD-010
H2: Fecha: 07/2026
H3: Revisión: 0
H4: Pagina: 1 de 1
B8: ENTRADA | D8: SALIDA
A9: FECHA | B9: PROVEEDOR | C9: CANTIDAD | D9: SOLICITANTE | E9: EQUIPO | F9: CANTIDAD2 | G9: N° NOTA DE ENTREGA | H9: EXISTENCIA
B10: EXISTENCIA | C10: 30 | H10: =Table_2245[[#This Row],[CANTIDAD]]-Table_2245[[#This Row],[CANTIDAD2]] -> 30
A11: 46231 | B11: ENVISERCA | C11: 15 | H11: =H10+Table_2245[[#This Row],[CANTIDAD]] -> 45
A12: 46275 | E12: JUMBO | F12: 15 | H12: =H11-Table_2245[[#This Row],[CANTIDAD2]] -> 30
A13: 46279 | E13: TALLER | F13: 15 | H13: =H12-Table_2245[[#This Row],[CANTIDAD2]] -> 15
H14: =H13-Table_2245[[#This Row],[CANTIDAD2]] -> 15
H15: =H14-Table_2245[[#This Row],[CANTIDAD2]] -> 15
H16: =H15-Table_2245[[#This Row],[CANTIDAD2]] -> 15
H17: =H16-Table_2245[[#This Row],[CANTIDAD2]] -> 15
H18: =H17-Table_2245[[#This Row],[CANTIDAD2]] -> 15
H19: =H18-Table_2245[[#This Row],[CANTIDAD2]] -> 15
H20: =H19-Table_2245[[#This Row],[CANTIDAD2]] -> 15
H21: =H20-Table_2245[[#This Row],[CANTIDAD2]] -> 15
H22: =H21-Table_2245[[#This Row],[CANTIDAD2]] -> 15
H23: =H22-Table_2245[[#This Row],[CANTIDAD2]] -> 15
H24: =H23-Table_2245[[#This Row],[CANTIDAD2]] -> 15
H25: =H24-Table_2245[[#This Row],[CANTIDAD2]] -> 15
... H43: =H42-Table_2245[[#This Row],[CANTIDAD2]] -> 15
F44: =F43-'GRASA LITHIUM 15 KG'!$E44+'GRASA LITHIUM 15 KG'!$D44 -> 0 | H44: =H43-Table_2245[[#This Row],[CANTIDAD2]] -> 15
H45: =H44-Table_2245[[#This Row],[CANTIDAD2]] -> 15
H46: =H45-Table_2245[[#This Row],[CANTIDAD2]] -> 15
H47: =H46-Table_2245[[#This Row],[CANTIDAD2]] -> 15
H48: =H47-Table_2245[[#This Row],[CANTIDAD2]] -> 15
H49: =H48-Table_2245[[#This Row],[CANTIDAD2]] -> 15
H50: =H49-Table_2245[[#This Row],[CANTIDAD2]] -> 15
H51: =H50-Table_2245[[#This Row],[CANTIDAD2]] -> 15
H52: =H51-Table_2245[[#This Row],[CANTIDAD2]] -> 15
H53: =H52-Table_2245[[#This Row],[CANTIDAD2]] -> 15
H54: =H53-Table_2245[[#This Row],[CANTIDAD2]] -> 15
H55: =H54-Table_2245[[#This Row],[CANTIDAD2]] -> 15
H56: =H55-Table_2245[[#This Row],[CANTIDAD2]] -> 15
... H70: =H69-Table_2245[[#This Row],[CANTIDAD2]] -> 15
H71: =Table_2245[[#This Row],[CANTIDAD]]-Table_2245[[#This Row],[CANTIDAD2]] -> 0
E72: =SUBTOTAL(109,'GRASA LITHIUM 15 KG'!$E$10:$E$71) -> 0
